Workbook

Sheet Dashboard Summary
A1: তারিখ ও সময় (Date & Time): | B1: 46179
A3: Main House Inventory & SR Summary Dashboard
A5: ১. হাউজের মূল স্টক হিসেব (Main House Inventory)
A6: প্রোডাক্টের নাম (Product) | B6: হাউজের ওপেনিং স্টক (Opening Stock) | C6: SR-দের দেওয়া হয়েছে (Total Issued) | D6: হাউজে বর্তমানে আছে (Current House Stock) | F6: নতুন করে আনা হয়েছে (Receive Product From Main House) | H6: পরিমান (Quantity)
A7: Sim | B7: 400 | C7: ='Daily Data Entry'!C5+'Daily Data Entry'!C17+'Daily Data Entry'!C29+'Daily Data Entry'!C41+'Daily Data Entry'!C53+'Daily Data Entry'!C65+'Daily Data Entry'!C77+'Daily Data Entry'!C89+'Daily Data Entry'!C101+'Daily Data Entry'!C113+'Daily Data Entry'!C125+'Daily Data Entry'!C137 -> 49 | D7: =B7-C7+D20+H7 -> 351 | F7: Sim | H7: 0
A8: Swap sim | B8: 90 | C8: ='Daily Data Entry'!C6+'Daily Data Entry'!C18+'Daily Data Entry'!C30+'Daily Data Entry'!C42+'Daily Data Entry'!C54+'Daily Data Entry'!C66+'Daily Data Entry'!C78+'Daily Data Entry'!C90+'Daily Data Entry'!C102+'Daily Data Entry'!C114+'Daily Data Entry'!C126+'Daily Data Entry'!C138 -> 29 | D8: =B8-C8+D21+H8 -> 61 | F8: Swap sim | H8: 0
A9: EV Swap sim | B9: 0 | C9: ='Daily Data Entry'!C7+'Daily Data Entry'!C19+'Daily Data Entry'!C31+'Daily Data Entry'!C43+'Daily Data Entry'!C55+'Daily Data Entry'!C67+'Daily Data Entry'!C79+'Daily Data Entry'!C91+'Daily Data Entry'!C103+'Daily Data Entry'!C115+'Daily Data Entry'!C127+'Daily Data Entry'!C139 -> 0 | D9: =B9-C9+D22+H9 -> 0 | F9: EV Swap sim | H9: 0
A10: 29 Taka Card | B10: 6060 | C10: ='Daily Data Entry'!C8+'Daily Data Entry'!C20+'Daily Data Entry'!C32+'Daily Data Entry'!C44+'Daily Data Entry'!C56+'Daily Data Entry'!C68+'Daily Data Entry'!C80+'Daily Data Entry'!C92+'Daily Data Entry'!C104+'Daily Data Entry'!C116+'Daily Data Entry'!C128+'Daily Data Entry'!C140 -> 1200 | D10: =B10-C10+D23+H10 -> 5090 | F10: 29 Taka Card | H10: 0
A11: 39 Taka Card | B11: 3170 | C11: ='Daily Data Entry'!C9+'Daily Data Entry'!C21+'Daily Data Entry'!C33+'Daily Data Entry'!C45+'Daily Data Entry'!C57+'Daily Data Entry'!C69+'Daily Data Entry'!C81+'Daily Data Entry'!C93+'Daily Data Entry'!C105+'Daily Data Entry'!C117+'Daily Data Entry'!C129+'Daily Data Entry'!C141 -> 150 | D11: =B11-C11+D24+H11 -> 3120 | F11: 39 Taka Card | H11: 0
A12: 49 Taka minute | B12: 1170 | C12: ='Daily Data Entry'!C10+'Daily Data Entry'!C22+'Daily Data Entry'!C34+'Daily Data Entry'!C46+'Daily Data Entry'!C58+'Daily Data Entry'!C70+'Daily Data Entry'!C82+'Daily Data Entry'!C94+'Daily Data Entry'!C106+'Daily Data Entry'!C118+'Daily Data Entry'!C130+'Daily Data Entry'!C142 -> 0 | D12: =B12-C12+D25+H12 -> 1170 | F12: 49 Taka minute | H12: 0
A13: 49 Taka MB card | B13: 4080 | C13: ='Daily Data Entry'!C11+'Daily Data Entry'!C23+'Daily Data Entry'!C35+'Daily Data Entry'!C47+'Daily Data Entry'!C59+'Daily Data Entry'!C71+'Daily Data Entry'!C83+'Daily Data Entry'!C95+'Daily Data Entry'!C107+'Daily Data Entry'!C119+'Daily Data Entry'!C131+'Daily Data Entry'!C143 -> 550 | D13: =B13-C13+D26+H13 -> 3790 | F13: 49 Taka MB card | H13: 0
A14: 39 Taka MB | B14: 180 | C14: ='Daily Data Entry'!C12+'Daily Data Entry'!C24+'Daily Data Entry'!C36+'Daily Data Entry'!C48+'Daily Data Entry'!C60+'Daily Data Entry'!C72+'Daily Data Entry'!C84+'Daily Data Entry'!C96+'Daily Data Entry'!C108+'Daily Data Entry'!C120+'Daily Data Entry'!C132+'Daily Data Entry'!C144 -> 0 | D14: =B14-C14+D27+H14 -> 180 | F14: 39 Taka MB | H14: 0
A15: 99 Taka minute | B15: 88 | C15: ='Daily Data Entry'!C13+'Daily Data Entry'!C25+'Daily Data Entry'!C37+'Daily Data Entry'!C49+'Daily Data Entry'!C61+'Daily Data Entry'!C73+'Daily Data Entry'!C85+'Daily Data Entry'!C97+'Daily Data Entry'!C109+'Daily Data Entry'!C121+'Daily Data Entry'!C133+'Daily Data Entry'!C145 -> 0 | D15: =B15-C15+D28+H15 -> 88 | F15: 99 Taka minute | H15: 0
A18: ২. মোট বিক্রি ও মার্কেট হোল্ড সামারি (Overall Sales & Market Hold)
A19: প্রোডাক্টের নাম (Product) | B19: আজকের মোট বিক্রি (Total Sales) | C19: SR-দের কাছে আটকে আছে (Total Hold in Market) | D19: SR-দের থেকে ফেরত (Total Return From SR)
A20: Sim | B20: ='Daily Data Entry'!E5+'Daily Data Entry'!E17+'Daily Data Entry'!E29+'Daily Data Entry'!E41+'Daily Data Entry'!E53+'Daily Data Entry'!E65+'Daily Data Entry'!E77+'Daily Data Entry'!E89+'Daily Data Entry'!E101+'Daily Data Entry'!E113+'Daily Data Entry'!E125+'Daily Data Entry'!E137 -> 12 | C20: ='Daily Data Entry'!G5+'Daily Data Entry'!G17+'Daily Data Entry'!G29+'Daily Data Entry'!G41+'Daily Data Entry'!G53+'Daily Data Entry'!G65+'Daily Data Entry'!G77+'Daily Data Entry'!G89+'Daily Data Entry'!G101+'Daily Data Entry'!G113+'Daily Data Entry'!G125+'Daily Data Entry'!G137 -> 364 | D20: ='Daily Data Entry'!F5+'Daily Data Entry'!F17+'Daily Data Entry'!F29+'Daily Data Entry'!F41+'Daily Data Entry'!F53+'Daily Data Entry'!F65+'Daily Data Entry'!F77+'Daily Data Entry'!F89+'Daily Data Entry'!F101+'Daily Data Entry'!F113+'Daily Data Entry'!F125+'Daily Data Entry'!F137 -> 0
A21: Swap sim | B21: ='Daily Data Entry'!E6+'Daily Data Entry'!E18+'Daily Data Entry'!E30+'Daily Data Entry'!E42+'Daily Data Entry'!E54+'Daily Data Entry'!E66+'Daily Data Entry'!E78+'Daily Data Entry'!E90+'Daily Data Entry'!E102+'Daily Data Entry'!E114+'Daily Data Entry'!E126+'Daily Data Entry'!E138 -> 25 | C21: ='Daily Data Entry'!G6+'Daily Data Entry'!G18+'Daily Data Entry'!G30+'Daily Data Entry'!G42+'Daily Data Entry'!G54+'Daily Data Entry'!G66+'Daily Data Entry'!G78+'Daily Data Entry'!G90+'Daily Data Entry'!G102+'Daily Data Entry'!G114+'Daily Data Entry'!G126+'Daily Data Entry'!G138 -> 91 | D21: ='Daily Data Entry'!F6+'Daily Data Entry'!F18+'Daily Data Entry'!F30+'Daily Data Entry'!F42+'Daily Data Entry'!F54+'Daily Data Entry'!F66+'Daily Data Entry'!F78+'Daily Data Entry'!F90+'Daily Data Entry'!F102+'Daily Data Entry'!F114+'Daily Data Entry'!F126+'Daily Data Entry'!F138 -> 0
A22: EV Swap sim | B22: ='Daily Data Entry'!E7+'Daily Data Entry'!E19+'Daily Data Entry'!E31+'Daily Data Entry'!E43+'Daily Data Entry'!E55+'Daily Data Entry'!E67+'Daily Data Entry'!E79+'Daily Data Entry'!E91+'Daily Data Entry'!E103+'Daily Data Entry'!E115+'Daily Data Entry'!E127+'Daily Data Entry'!E139 -> 0 | C22: ='Daily Data Entry'!G7+'Daily Data Entry'!G19+'Daily Data Entry'!G31+'Daily Data Entry'!G43+'Daily Data Entry'!G55+'Daily Data Entry'!G67+'Daily Data Entry'!G79+'Daily Data Entry'!G91+'Daily Data Entry'!G103+'Daily Data Entry'!G115+'Daily Data Entry'!G127+'Daily Data Entry'!G139 -> 0 | D22: ='Daily Data Entry'!F7+'Daily Data Entry'!F19+'Daily Data Entry'!F31+'Daily Data Entry'!F43+'Daily Data Entry'!F55+'Daily Data Entry'!F67+'Daily Data Entry'!F79+'Daily Data Entry'!F91+'Daily Data Entry'!F103+'Daily Data Entry'!F115+'Daily Data Entry'!F127+'Daily Data Entry'!F139 -> 0
A23: 29 Taka Card | B23: ='Daily Data Entry'!E8+'Daily Data Entry'!E20+'Daily Data Entry'!E32+'Daily Data Entry'!E44+'Daily Data Entry'!E56+'Daily Data Entry'!E68+'Daily Data Entry'!E80+'Daily Data Entry'!E92+'Daily Data Entry'!E104+'Daily Data Entry'!E116+'Daily Data Entry'!E128+'Daily Data Entry'!E140 -> 870 | C23: ='Daily Data Entry'!G8+'Daily Data Entry'!G20+'Daily Data Entry'!G32+'Daily Data Entry'!G44+'Daily Data Entry'!G56+'Daily Data Entry'!G68+'Daily Data Entry'!G80+'Daily Data Entry'!G92+'Daily Data Entry'!G104+'Daily Data Entry'!G116+'Daily Data Entry'!G128+'Daily Data Entry'!G140 -> 3970 | D23: ='Daily Data Entry'!F8+'Daily Data Entry'!F20+'Daily Data Entry'!F32+'Daily Data Entry'!F44+'Daily Data Entry'!F56+'Daily Data Entry'!F68+'Daily Data Entry'!F80+'Daily Data Entry'!F92+'Daily Data Entry'!F104+'Daily Data Entry'!F116+'Daily Data Entry'!F128+'Daily Data Entry'!F140 -> 230
A24: 39 Taka Card | B24: ='Daily Data Entry'!E9+'Daily Data Entry'!E21+'Daily Data Entry'!E33+'Daily Data Entry'!E45+'Daily Data Entry'!E57+'Daily Data Entry'!E69+'Daily Data Entry'!E81+'Daily Data Entry'!E93+'Daily Data Entry'!E105+'Daily Data Entry'!E117+'Daily Data Entry'!E129+'Daily Data Entry'!E141 -> 220 | C24: ='Daily Data Entry'!G9+'Daily Data Entry'!G21+'Daily Data Entry'!G33+'Daily Data Entry'!G45+'Daily Data Entry'!G57+'Daily Data Entry'!G69+'Daily Data Entry'!G81+'Daily Data Entry'!G93+'Daily Data Entry'!G105+'Daily Data Entry'!G117+'Daily Data Entry'!G129+'Daily Data Entry'!G141 -> 1580 | D24: ='Daily Data Entry'!F9+'Daily Data Entry'!F21+'Daily Data Entry'!F33+'Daily Data Entry'!F45+'Daily Data Entry'!F57+'Daily Data Entry'!F69+'Daily Data Entry'!F81+'Daily Data Entry'!F93+'Daily Data Entry'!F105+'Daily Data Entry'!F117+'Daily Data Entry'!F129+'Daily Data Entry'!F141 -> 100
A25: 49 Taka minute | B25: ='Daily Data Entry'!E10+'Daily Data Entry'!E22+'Daily Data Entry'!E34+'Daily Data Entry'!E46+'Daily Data Entry'!E58+'Daily Data Entry'!E70+'Daily Data Entry'!E82+'Daily Data Entry'!E94+'Daily Data Entry'!E106+'Daily Data Entry'!E118+'Daily Data Entry'!E130+'Daily Data Entry'!E142 -> 0 | C25: ='Daily Data Entry'!G10+'Daily Data Entry'!G22+'Daily Data Entry'!G34+'Daily Data Entry'!G46+'Daily Data Entry'!G58+'Daily Data Entry'!G70+'Daily Data Entry'!G82+'Daily Data Entry'!G94+'Daily Data Entry'!G106+'Daily Data Entry'!G118+'Daily Data Entry'!G130+'Daily Data Entry'!G142 -> 240 | D25: ='Daily Data Entry'!F10+'Daily Data Entry'!F22+'Daily Data Entry'!F34+'Daily Data Entry'!F46+'Daily Data Entry'!F58+'Daily Data Entry'!F70+'Daily Data Entry'!F82+'Daily Data Entry'!F94+'Daily Data Entry'!F106+'Daily Data Entry'!F118+'Daily Data Entry'!F130+'Daily Data Entry'!F142 -> 0
A26: 49 Taka MB card | B26: ='Daily Data Entry'!E11+'Daily Data Entry'!E23+'Daily Data Entry'!E35+'Daily Data Entry'!E47+'Daily Data Entry'!E59+'Daily Data Entry'!E71+'Daily Data Entry'!E83+'Daily Data Entry'!E95+'Daily Data Entry'!E107+'Daily Data Entry'!E119+'Daily Data Entry'!E131+'Daily Data Entry'!E143 -> 130 | C26: ='Daily Data Entry'!G11+'Daily Data Entry'!G23+'Daily Data Entry'!G35+'Daily Data Entry'!G47+'Daily Data Entry'!G59+'Daily Data Entry'!G71+'Daily Data Entry'!G83+'Daily Data Entry'!G95+'Daily Data Entry'!G107+'Daily Data Entry'!G119+'Daily Data Entry'!G131+'Daily Data Entry'!G143 -> 1540 | D26: ='Daily Data Entry'!F11+'Daily Data Entry'!F23+'Daily Data Entry'!F35+'Daily Data Entry'!F47+'Daily Data Entry'!F59+'Daily Data Entry'!F71+'Daily Data Entry'!F83+'Daily Data Entry'!F95+'Daily Data Entry'!F107+'Daily Data Entry'!F119+'Daily Data Entry'!F131+'Daily Data Entry'!F143 -> 260
A27: 39 Taka MB | B27: ='Daily Data Entry'!E12+'Daily Data Entry'!E24+'Daily Data Entry'!E36+'Daily Data Entry'!E48+'Daily Data Entry'!E60+'Daily Data Entry'!E72+'Daily Data Entry'!E84+'Daily Data Entry'!E96+'Daily Data Entry'!E108+'Daily Data Entry'!E120+'Daily Data Entry'!E132+'Daily Data Entry'!E144 -> 0 | C27: ='Daily Data Entry'!G12+'Daily Data Entry'!G24+'Daily Data Entry'!G36+'Daily Data Entry'!G48+'Daily Data Entry'!G60+'Daily Data Entry'!G72+'Daily Data Entry'!G84+'Daily Data Entry'!G96+'Daily Data Entry'!G108+'Daily Data Entry'!G120+'Daily Data Entry'!G132+'Daily Data Entry'!G144 -> 0 | D27: ='Daily Data Entry'!F12+'Daily Data Entry'!F24+'Daily Data Entry'!F36+'Daily Data Entry'!F48+'Daily Data Entry'!F60+'Daily Data Entry'!F72+'Daily Data Entry'!F84+'Daily Data Entry'!F96+'Daily Data Entry'!F108+'Daily Data Entry'!F120+'Daily Data Entry'!F132+'Daily Data Entry'!F144 -> 0
A28: 99 Taka minute | B28: ='Daily Data Entry'!E13+'Daily Data Entry'!E25+'Daily Data Entry'!E37+'Daily Data Entry'!E49+'Daily Data Entry'!E61+'Daily Data Entry'!E73+'Daily Data Entry'!E85+'Daily Data Entry'!E97+'Daily Data Entry'!E109+'Daily Data Entry'!E121+'Daily Data Entry'!E133+'Daily Data Entry'!E145 -> 0 | C28: ='Daily Data Entry'!G13+'Daily Data Entry'!G25+'Daily Data Entry'!G37+'Daily Data Entry'!G49+'Daily Data Entry'!G61+'Daily Data Entry'!G73+'Daily Data Entry'!G85+'Daily Data Entry'!G97+'Daily Data Entry'!G109+'Daily Data Entry'!G121+'Daily Data Entry'!G133+'Daily Data Entry'!G145 -> 0 | D28: ='Daily Data Entry'!F13+'Daily Data Entry'!F25+'Daily Data Entry'!F37+'Daily Data Entry'!F49+'Daily Data Entry'!F61+'Daily Data Entry'!F73+'Daily Data Entry'!F85+'Daily Data Entry'!F97+'Daily Data Entry'!F109+'Daily Data Entry'!F121+'Daily Data Entry'!F133+'Daily Data Entry'!F145 -> 0
A31: ৩. কার কাছে বর্তমানে কি প্রোডাক্ট রয়েছে (SR Wise Closing Stock Breakdown)
A32: SR-এর নাম (SR Name) | B32: Sim | C32: Swap sim | D32: EV Swap sim | E32: 29 Taka Card | F32: 39 Taka Card | G32: 49 Taka minute | H32: 49 Taka MB card | I32: 39 Taka MB | J32: 99 Taka minute
A33: Rubel | B33: ='Daily Data Entry'!G5 -> 47 | C33: ='Daily Data Entry'!G6 -> 19 | D33: ='Daily Data Entry'!G7 -> 0 | E33: ='Daily Data Entry'!G8 -> 350 | F33: ='Daily Data Entry'!G9 -> 450 | G33: ='Daily Data Entry'!G10 -> 50 | H33: ='Daily Data Entry'!G11 -> 340 | I33: ='Daily Data Entry'!G12 -> 0 | J33: ='Daily Data Entry'!G13 -> 0
A34: Razo | B34: ='Daily Data Entry'!G17 -> 12 | C34: ='Daily Data Entry'!G18 -> 10 | D34: ='Daily Data Entry'!G19 -> 0 | E34: ='Daily Data Entry'!G20 -> 0 | F34: ='Daily Data Entry'!G21 -> 0 | G34: ='Daily Data Entry'!G22 -> 0 | H34: ='Daily Data Entry'!G23 -> 0 | I34: ='Daily Data Entry'!G24 -> 0 | J34: ='Daily Data Entry'!G25 -> 0
A35: Fazlo | B35: ='Daily Data Entry'!G29 -> 24 | C35: ='Daily Data Entry'!G30 -> 5 | D35: ='Daily Data Entry'!G31 -> 0 | E35: ='Daily Data Entry'!G32 -> 2340 | F35: ='Daily Data Entry'!G33 -> 250 | G35: ='Daily Data Entry'!G34 -> 0 | H35: ='Daily Data Entry'!G35 -> 140 | I35: ='Daily Data Entry'!G36 -> 0 | J35: ='Daily Data Entry'!G37 -> 0
A36: Mijanur | B36: ='Daily Data Entry'!G41 -> 15 | C36: ='Daily Data Entry'!G42 -> 10 | D36: ='Daily Data Entry'!G43 -> 0 | E36: ='Daily Data Entry'!G44 -> 0 | F36: ='Daily Data Entry'!G45 -> 0 | G36: ='Daily Data Entry'!G46 -> 0 | H36: ='Daily Data Entry'!G47 -> 0 | I36: ='Daily Data Entry'!G48 -> 0 | J36: ='Daily Data Entry'!G49 -> 0
A37: Robin | B37: ='Daily Data Entry'!G53 -> 6 | C37: ='Daily Data Entry'!G54 -> 5 | D37: ='Daily Data Entry'!G55 -> 0 | E37: ='Daily Data Entry'!G56 -> 100 | F37: ='Daily Data Entry'!G57 -> 0 | G37: ='Daily Data Entry'!G58 -> 0 | H37: ='Daily Data Entry'!G59 -> 0 | I37: ='Daily Data Entry'!G60 -> 0 | J37: ='Daily Data Entry'!G61 -> 0
A38: Zihad | B38: ='Daily Data Entry'!G65 -> 42 | C38: ='Daily Data Entry'!G66 -> 0 | D38: ='Daily Data Entry'!G67 -> 0 | E38: ='Daily Data Entry'!G68 -> 900 | F38: ='Daily Data Entry'!G69 -> 650 | G38: ='Daily Data Entry'!G70 -> 100 | H38: ='Daily Data Entry'!G71 -> 650 | I38: ='Daily Data Entry'!G72 -> 0 | J38: ='Daily Data Entry'!G73 -> 0
A39: Masud | B39: ='Daily Data Entry'!G77 -> 34 | C39: ='Daily Data Entry'!G78 -> 0 | D39: ='Daily Data Entry'!G79 -> 0 | E39: ='Daily Data Entry'!G80 -> 0 | F39: ='Daily Data Entry'!G81 -> 0 | G39: ='Daily Data Entry'!G82 -> 0 | H39: ='Daily Data Entry'!G83 -> 0 | I39: ='Daily Data Entry'!G84 -> 0 | J39: ='Daily Data Entry'!G85 -> 0
A40: Al amin | B40: ='Daily Data Entry'!G89 -> 55 | C40: ='Daily Data Entry'!G90 -> 10 | D40: ='Daily Data Entry'!G91 -> 0 | E40: ='Daily Data Entry'!G92 -> 0 | F40: ='Daily Data Entry'!G93 -> 0 | G40: ='Daily Data Entry'!G94 -> 0 | H40: ='Daily Data Entry'!G95 -> 0 | I40: ='Daily Data Entry'!G96 -> 0 | J40: ='Daily Data Entry'!G97 -> 0
A41: Minhaj | B41: ='Daily Data Entry'!G101 -> 10 | C41: ='Daily Data Entry'!G102 -> 2 | D41: ='Daily Data Entry'!G103 -> 0 | E41: ='Daily Data Entry'!G104 -> 0 | F41: ='Daily Data Entry'!G105 -> 0 | G41: ='Daily Data Entry'!G106 -> 0 | H41: ='Daily Data Entry'!G107 -> 0 | I41: ='Daily Data Entry'!G108 -> 0 | J41: ='Daily Data Entry'!G109 -> 0
A42: Asad | B42: ='Daily Data Entry'!G113 -> 22 | C42: ='Daily Data Entry'!G114 -> 25 | D42: ='Daily Data Entry'!G115 -> 0 | E42: ='Daily Data Entry'!G116 -> 280 | F42: ='Daily Data Entry'!G117 -> 230 | G42: ='Daily Data Entry'!G118 -> 90 | H42: ='Daily Data Entry'!G119 -> 410 | I42: ='Daily Data Entry'!G120 -> 0 | J42: ='Daily Data Entry'!G121 -> 0
A43: Alamgir | B43: ='Daily Data Entry'!G125 -> 22 | C43: ='Daily Data Entry'!G126 -> 0 | D43: ='Daily Data Entry'!G127 -> 0 | E43: ='Daily Data Entry'!G128 -> 0 | F43: ='Daily Data Entry'!G129 -> 0 | G43: ='Daily Data Entry'!G130 -> 0 | H43: ='Daily Data Entry'!G131 -> 0 | I43: ='Daily Data Entry'!G132 -> 0 | J43: ='Daily Data Entry'!G133 -> 0
A44: Tamjin | B44: ='Daily Data Entry'!G137 -> 75 | C44: ='Daily Data Entry'!G138 -> 5 | D44: ='Daily Data Entry'!G139 -> 0 | E44: ='Daily Data Entry'!G140 -> 0 | F44: ='Daily Data Entry'!G141 -> 0 | G44: ='Daily Data Entry'!G142 -> 0 | H44: ='Daily Data Entry'!G143 -> 0 | I44: ='Daily Data Entry'!G144 -> 0 | J44: ='Daily Data Entry'!G145 -> 0
A45: Total | B45: =SUM(B33:B44) -> 364 | C45: =SUM(C33:C44) -> 91 | D45: =SUM(D33:D44) -> 0 | E45: =SUM(E33:E44) -> 3970 | F45: =SUM(F33:F44) -> 1580 | G45: =SUM(G33:G44) -> 240 | H45: =SUM(H33:H44) -> 1540 | I45: =SUM(I33:I44) -> 0 | J45: =SUM(J33:J44) -> 0

Sheet Daily Data Entry
A1: Daily SR Issue, Sales & Return Entry
A3: RSO: Rubel
A4: প্রোডাক্টের নাম (Product) | B4: আগের দিনের বাকি (Opening) | C4: নতুন ইস্যু (New Issue) | D4: মোট স্টক (Total Stock) | E4: বিক্রি (Sales) | F4: ফেরত (Return) | G4: কাছে রয়ে গেলো (Closing)
A5: Sim | B5: 37 | C5: 10 | D5: =B5+C5 -> 47 | E5: 0 | F5: 0 | G5: =D5-E5-F5 -> 47
A6: Swap sim | B6: 15 | C6: 4 | D6: =B6+C6 -> 19 | E6: 0 | F6: 0 | G6: =D6-E6-F6 -> 19
A7: EV Swap sim | B7: 0 | C7: 0 | D7: =B7+C7 -> 0 | E7: 0 | F7: 0 | G7: =D7-E7-F7 -> 0
A8: 29 Taka Card | B8: 50 | C8: 500 | D8: =B8+C8 -> 550 | E8: 200 | F8: 0 | G8: =D8-E8-F8 -> 350
A9: 39 Taka Card | B9: 450 | C9: 0 | D9: =B9+C9 -> 450 | E9: 0 | F9: 0 | G9: =D9-E9-F9 -> 450
A10: 49 Taka minute | B10: 50 | C10: 0 | D10: =B10+C10 -> 50 | E10: 0 | F10: 0 | G10: =D10-E10-F10 -> 50
A11: 49 Taka MB card | B11: 140 | C11: 200 | D11: =B11+C11 -> 340 | E11: 0 | F11: 0 | G11: =D11-E11-F11 -> 340
A12: 39 Taka MB | B12: 0 | C12: 0 | D12: =B12+C12 -> 0 | E12: 0 | F12: 0 | G12: =D12-E12-F12 -> 0
A13: 99 Taka minute | B13: 0 | C13: 0 | D13: =B13+C13 -> 0 | E13: 0 | F13: 0 | G13: =D13-E13-F13 -> 0
A15: RSO: Razo
A16: প্রোডাক্টের নাম (Product) | B16: আগের দিনের বাকি (Opening) | C16: নতুন ইস্যু (New Issue) | D16: মোট স্টক (Total Stock) | E16: বিক্রি (Sales) | F16: ফেরত (Return) | G16: কাছে রয়ে গেলো (Closing)
A17: Sim | B17: 14 | C17: 0 | D17: =B17+C17 -> 14 | E17: 2 | F17: 0 | G17: =D17-E17-F17 -> 12
A18: Swap sim | B18: 10 | C18: 0 | D18: =B18+C18 -> 10 | E18: 0 | F18: 0 | G18: =D18-E18-F18 -> 10
A19: EV Swap sim | B19: 0 | C19: 0 | D19: =B19+C19 -> 0 | E19: 0 | F19: 0 | G19: =D19-E19-F19 -> 0
A20: 29 Taka Card | B20: 0 | C20: 0 | D20: =B20+C20 -> 0 | E20: 0 | F20: 0 | G20: =D20-E20-F20 -> 0
A21: 39 Taka Card | B21: 0 | C21: 0 | D21: =B21+C21 -> 0 | E21: 0 | F21: 0 | G21: =D21-E21-F21 -> 0
A22: 49 Taka minute | B22: 0 | C22: 0 | D22: =B22+C22 -> 0 | E22: 0 | F22: 0 | G22: =D22-E22-F22 -> 0
A23: 49 Taka MB card | B23: 0 | C23: 0 | D23: =B23+C23 -> 0 | E23: 0 | F23: 0 | G23: =D23-E23-F23 -> 0
A24: 39 Taka MB | B24: 0 | C24: 0 | D24: =B24+C24 -> 0 | E24: 0 | F24: 0 | G24: =D24-E24-F24 -> 0
A25: 99 Taka minute | B25: 0 | C25: 0 | D25: =B25+C25 -> 0 | E25: 0 | F25: 0 | G25: =D25-E25-F25 -> 0
A27: RSO: Fazlo
A28: প্রোডাক্টের নাম (Product) | B28: আগের দিনের বাকি (Opening) | C28: নতুন ইস্যু (New Issue) | D28: মোট স্টক (Total Stock) | E28: বিক্রি (Sales) | F28: ফেরত (Return) | G28: কাছে রয়ে গেলো (Closing)
A29: Sim | B29: 24 | C29: 0 | D29: =B29+C29 -> 24 | E29: 0 | F29: 0 | G29: =D29-E29-F29 -> 24
A30: Swap sim | B30: 5 | C30: 0 | D30: =B30+C30 -> 5 | E30: 0 | F30: 0 | G30: =D30-E30-F30 -> 5
A31: EV Swap sim | B31: 0 | C31: 0 | D31: =B31+C31 -> 0 | E31: 0 | F31: 0 | G31: =D31-E31-F31 -> 0
A32: 29 Taka Card | B32: 2340 | C32: 0 | D32: =B32+C32 -> 2340 | E32: 0 | F32: 0 | G32: =D32-E32-F32 -> 2340
A33: 39 Taka Card | B33: 250 | C33: 0 | D33: =B33+C33 -> 250 | E33: 0 | F33: 0 | G33: =D33-E33-F33 -> 250
A34: 49 Taka minute | B34: 0 | C34: 0 | D34: =B34+C34 -> 0 | E34: 0 | F34: 0 | G34: =D34-E34-F34 -> 0
A35: 49 Taka MB card | B35: 140 | C35: 0 | D35: =B35+C35 -> 140 | E35: 0 | F35: 0 | G35: =D35-E35-F35 -> 140
A36: 39 Taka MB | B36: 0 | C36: 0 | D36: =B36+C36 -> 0 | E36: 0 | F36: 0 | G36: =D36-E36-F36 -> 0
A37: 99 Taka minute | B37: 0 | C37: 0 | D37: =B37+C37 -> 0 | E37: 0 | F37: 0 | G37: =D37-E37-F37 -> 0
A39: RSO: Mijanur
A40: প্রোডাক্টের নাম (Product) | B40: আগের দিনের বাকি (Opening) | C40: নতুন ইস্যু (New Issue) | D40: মোট স্টক (Total Stock) | E40: বিক্রি (Sales) | F40: ফেরত (Return) | G40: কাছে রয়ে গেলো (Closing)
A41: Sim | B41: 5 | C41: 10 | D41: =B41+C41 -> 15 | E41: 0 | F41: 0 | G41: =D41-E41-F41 -> 15
A42: Swap sim | B42: 10 | C42: 0 | D42: =B42+C42 -> 10 | E42: 0 | F42: 0 | G42: =D42-E42-F42 -> 10
A43: EV Swap sim | B43: 0 | C43: 0 | D43: =B43+C43 -> 0 | E43: 0 | F43: 0 | G43: =D43-E43-F43 -> 0
A44: 29 Taka Card | B44: 0 | C44: 100 | D44: =B44+C44 -> 100 | E44: 50 | F44: 50 | G44: =D44-E44-F44 -> 0
...

Sheet Daily Profit & Accounts
A1: Daily Profit & Accounts Tracker
A3: প্রোডাক্ট ভিত্তিক লাভ-ক্ষতি হিসেব (Product-wise Profit/Loss)
A4: প্রোডাক্টের নাম (Product Name) | B4: আজকের মোট বিক্রি সংখ্যা (Total Qty Sold) | C4: ইউনিট কেনা দাম (Cost Price/Unit) | D4: স্বাভাবিক বিক্রি দাম (Reg. Sale Price/Unit) | E4: ডিসকাউন্ট/লেস দেওয়া মূল্য (Less/Discount Total) | F4: মোট কেনা দাম (Total Cost) | G4: মোট প্রকৃত বিক্রি মূল্য (Total Revenue) | H4: মোট প্রফিট (Net Profit)
A5: Sim | B5: ='Dashboard Summary'!B20 -> 12 | C5: 300 | D5: 300 | E5: 0 | F5: =B5*C5 -> 3600 | G5: =(B5*D5)-E5 -> 3600 | H5: =G5-F5 -> 0
A6: Swap sim | B6: ='Dashboard Summary'!B21 -> 25 | C6: 323 | D6: 340 | E6: 0 | F6: =B6*C6 -> 8075 | G6: =(B6*D6)-E6 -> 8500 | H6: =G6-F6 -> 425
A7: EV Swap sim | B7: ='Dashboard Summary'!B22 -> 0 | C7: 100 | D7: 100 | E7: 0 | F7: =B7*C7 -> 0 | G7: =(B7*D7)-E7 -> 0 | H7: =G7-F7 -> 0
A8: 29 Taka Card | B8: ='Dashboard Summary'!B23 -> 870 | C8: 27.9125 | D8: 28 | E8: 0 | F8: =B8*C8 -> 24283.875 | G8: =(B8*D8)-E8 -> 24360 | H8: =G8-F8 -> 76.125
A9: 39 Taka Card | B9: ='Dashboard Summary'!B24 -> 220 | C9: 37.5375 | D9: 38 | E9: 0 | F9: =B9*C9 -> 8258.25 | G9: =(B9*D9)-E9 -> 8360 | H9: =G9-F9 -> 101.75
A10: 49 Taka minute | B10: ='Dashboard Summary'!B25 -> 0 | C10: 47.1625 | D10: 48 | E10: 0 | F10: =B10*C10 -> 0 | G10: =(B10*D10)-E10 -> 0 | H10: =G10-F10 -> 0
A11: 49 Taka MB card | B11: ='Dashboard Summary'!B26 -> 130 | C11: 47.1625 | D11: 48 | E11: 0 | F11: =B11*C11 -> 6131.125 | G11: =(B11*D11)-E11 -> 6240 | H11: =G11-F11 -> 108.875
A12: 39 Taka MB | B12: ='Dashboard Summary'!B27 -> 0 | C12: 37.5375 | D12: 38 | E12: 0 | F12: =B12*C12 -> 0 | G12: =(B12*D12)-E12 -> 0 | H12: =G12-F12 -> 0
A13: 99 Taka minute | B13: ='Dashboard Summary'!B28 -> 0 | C13: 95.2875 | D13: 97 | E13: 0 | F13: =B13*C13 -> 0 | G13: =(B13*D13)-E13 -> 0 | H13: =G13-F13 -> 0
A14: মোট প্রোডাক্ট প্রফিট (Total Product Profit) | G14: =SUM(G5:G13) -> 51060 | H14: =SUM(H5:H13) -> 711.75
